ValueError
Python 3.9.8: F:\File_my\Project\Plug-in_1\Pyqt\venv64\Scripts\python.exe
Fri Jun 10 12:47:01 2022

A problem occurred in a Python script.  Here is the sequence of
function calls leading up to the error, in the order they occurred.

 F:\File_my\Project\Plug-in_1\Pyqt\designerFile\index.py in updateData(self=<designerFile.index.MyMainForm object>, row=2, col=4)
  837                                 count = int(GVWindex * 26)
  838                                 t = int(GVWindex) - 26 * count
  839                                 x = chr(t + 65)
  840                                 x = chr(65 + count - 1) + x
  841                                 item = x + str(row + 1)
x = 'Z'
builtinchr = <built-in function chr>
t = -18900
ValueError: chr() arg not in range(0x110000)
    __cause__ = None
    __class__ = <class 'ValueError'>
    __context__ = None
    __delattr__ = <method-wrapper '__delattr__' of ValueError object>
    __dict__ = {}
    __dir__ = <built-in method __dir__ of ValueError object>
    __doc__ = 'Inappropriate argument value (of correct type).'
    __eq__ = <method-wrapper '__eq__' of ValueError object>
    __format__ = <built-in method __format__ of ValueError object>
    __ge__ = <method-wrapper '__ge__' of ValueError object>
    __getattribute__ = <method-wrapper '__getattribute__' of ValueError object>
    __gt__ = <method-wrapper '__gt__' of ValueError object>
    __hash__ = <method-wrapper '__hash__' of ValueError object>
    __init__ = <method-wrapper '__init__' of ValueError object>
    __init_subclass__ = <built-in method __init_subclass__ of type object>
    __le__ = <method-wrapper '__le__' of ValueError object>
    __lt__ = <method-wrapper '__lt__' of ValueError object>
    __ne__ = <method-wrapper '__ne__' of ValueError object>
    __new__ = <built-in method __new__ of type object>
    __reduce__ = <built-in method __reduce__ of ValueError object>
    __reduce_ex__ = <built-in method __reduce_ex__ of ValueError object>
    __repr__ = <method-wrapper '__repr__' of ValueError object>
    __setattr__ = <method-wrapper '__setattr__' of ValueError object>
    __setstate__ = <built-in method __setstate__ of ValueError object>
    __sizeof__ = <built-in method __sizeof__ of ValueError object>
    __str__ = <method-wrapper '__str__' of ValueError object>
    __subclasshook__ = <built-in method __subclasshook__ of type object>
    __suppress_context__ = False
    __traceback__ = <traceback object>
    args = ('chr() arg not in range(0x110000)',)
    with_traceback = <built-in method with_traceback of ValueError object>

The above is a description of an error in a Python program.  Here is
the original traceback:

Traceback (most recent call last):
  File "F:\File_my\Project\Plug-in_1\Pyqt\designerFile\index.py", line 839, in updateData
    x = chr(t + 65)
ValueError: chr() arg not in range(0x110000)

